<?xml version="1.0" encoding="utf-8"?>
<robot name="ur5e_robotiq">

  <!-- ========== UR5e Robot Links and Joints ========== -->

  <!-- Base Link -->
  <link name="base_link">
    <visual>
      <origin rpy="0 0 3.14159265359" xyz="0 0 0.0" />
      <geometry>
        <mesh filename="../meshes/ur5e_update/visual/base.dae" />
      </geometry>
      <material name="LightGrey">
        <color rgba="0.8 0.8 0.8 1.0" />
      </material>
    </visual>
    <collision>
      <origin rpy="0 0 3.14159265359" xyz="0 0 0.0" />
      <geometry>
        <mesh filename="../meshes/ur5e_update/collision/base.stl" />
      </geometry>
    </collision>
    <inertial>
      <mass value="4.0" />
      <origin rpy="0 0 0" xyz="0.0 0.0 0.0" />
      <inertia ixx="0.00443333156" ixy="0.0" ixz="0.0" iyy="0.00443333156" iyz="0.0" izz="0.0072" />
    </inertial>
  </link>

  <!-- Shoulder Pan Joint -->
  <joint name="shoulder_pan_joint" type="revolute">
    <parent link="base_link" />
    <child link="shoulder_link" />
    <origin rpy="0 0 0" xyz="0 0 0.1625" />
    <axis xyz="0 0 1" />
    <limit effort="150.0" lower="-6.283185307179586" upper="6.283185307179586" velocity="3.14" />
    <dynamics damping="0.0" friction="0.0" />
  </joint>

  <!-- Shoulder Link -->
  <link name="shoulder_link">
    <visual>
      <geometry>
        <mesh filename="../meshes/ur5e_update/visual/shoulder.dae" />
      </geometry>
      <material name="UR_Blue">
        <color rgba="0.376 0.576 0.674 1.0" />
      </material>
    </visual>
    <collision>
      <geometry>
        <mesh filename="../meshes/ur5e_update/collision/shoulder.stl" />
      </geometry>
    </collision>
    <inertial>
      <mass value="3.7" />
      <origin rpy="0 0 0" xyz="0.0 0.0 0.0" />
      <inertia ixx="0.010267495893" ixy="0.0" ixz="0.0" iyy="0.010267495893" iyz="0.0" izz="0.00666" />
    </inertial>
  </link>

  <!-- Shoulder Lift Joint -->
  <joint name="shoulder_lift_joint" type="revolute">
    <parent link="shoulder_link" />
    <child link="upper_arm_link" />
    <origin rpy="0 1.570796327 0" xyz="0 0.138 0" />
    <axis xyz="0 1 0" />
    <limit effort="150.0" lower="-6.283185307179586" upper="6.283185307179586" velocity="3.14" />
    <dynamics damping="0.0" friction="0.0" />
  </joint>

  <!-- Upper Arm Link -->
  <link name="upper_arm_link">
    <visual>
      <geometry>
        <mesh filename="../meshes/ur5e_update/visual/upperarm.dae" />
      </geometry>
      <material name="LightGrey">
        <color rgba="0.8 0.8 0.8 1.0" />
      </material>
    </visual>
    <collision>
      <geometry>
        <mesh filename="../meshes/ur5e_update/collision/upperarm.stl" />
      </geometry>
    </collision>
    <inertial>
      <mass value="8.393" />
      <origin rpy="0 1.57079632679 0" xyz="-0.2125 0.0 0.138" />
      <inertia ixx="0.138134736413" ixy="0.0" ixz="0.0" iyy="0.138134736413" iyz="0.0"
        izz="0.0236053125" />
    </inertial>
  </link>

  <!-- Elbow Joint -->
  <joint name="elbow_joint" type="revolute">
    <parent link="upper_arm_link" />
    <child link="forearm_link" />
    <origin rpy="0 0 0" xyz="0 -0.131 0.425" />
    <axis xyz="0 1 0" />
    <limit effort="150.0" lower="-6.283185307179586" upper="6.283185307179586" velocity="3.14" />
    <dynamics damping="0.0" friction="0.0" />
  </joint>

  <!-- Forearm Link -->
  <link name="forearm_link">
    <visual>
      <geometry>
        <mesh filename="../meshes/ur5e_update/visual/forearm.dae" />
      </geometry>
      <material name="LightGrey">
        <color rgba="0.8 0.8 0.8 1.0" />
      </material>
    </visual>
    <collision>
      <geometry>
        <mesh filename="../meshes/ur5e_update/collision/forearm.stl" />
      </geometry>
    </collision>
    <inertial>
      <mass value="2.275" />
      <origin rpy="0 1.57079632679 0" xyz="-0.2125 0.0 0.007" />
      <inertia ixx="0.0323610733889" ixy="0.0" ixz="0.0" iyy="0.0323610733889" iyz="0.0"
        izz="0.0063984375" />
    </inertial>
  </link>

  <!-- Wrist 1 Joint -->
  <joint name="wrist_1_joint" type="revolute">
    <parent link="forearm_link" />
    <child link="wrist_1_link" />
    <origin rpy="0 1.5708 0" xyz="0 0 0.3922" />
    <axis xyz="0 1 0" />
    <limit effort="28.0" lower="-6.283185307179586" upper="6.283185307179586" velocity="6.28" />
    <dynamics damping="0.0" friction="0.0" />
  </joint>

  <!-- Wrist 1 Link -->
  <link name="wrist_1_link">
    <visual>
      <geometry>
        <mesh filename="../meshes/ur5e_update/visual/wrist1.dae" />
      </geometry>
      <material name="UR_Blue">
        <color rgba="0.376 0.576 0.674 1.0" />
      </material>
    </visual>
    <collision>
      <geometry>
        <mesh filename="../meshes/ur5e_update/collision/wrist1.stl" />
      </geometry>
    </collision>
    <inertial>
      <mass value="1.219" />
      <origin rpy="0 0 0" xyz="0.0 0.0 0.0" />
      <inertia ixx="0.00272396513625" ixy="0.0" ixz="0.0" iyy="0.00272396513625" iyz="0.0"
        izz="0.0034284375" />
    </inertial>
  </link>

  <!-- Wrist 2 Joint -->
  <joint name="wrist_2_joint" type="revolute">
    <parent link="wrist_1_link" />
    <child link="wrist_2_link" />
    <origin rpy="0 0 0" xyz="0 0.127 0" />
    <axis xyz="0 0 1" />
    <limit effort="28.0" lower="-6.283185307179586" upper="6.283185307179586" velocity="6.28" />
    <dynamics damping="0.0" friction="0.0" />
  </joint>

  <!-- Wrist 2 Link -->
  <link name="wrist_2_link">
    <visual>
      <geometry>
        <mesh filename="../meshes/ur5e_update/visual/wrist2.dae" />
      </geometry>
      <material name="LightGrey">
        <color rgba="0.8 0.8 0.8 1.0" />
      </material>
    </visual>
    <collision>
      <geometry>
        <mesh filename="../meshes/ur5e_update/collision/wrist2.stl" />
      </geometry>
    </collision>
    <inertial>
      <mass value="1.219" />
      <origin rpy="0 0 0" xyz="0.0 0.0 0.0" />
      <inertia ixx="0.00272194058122" ixy="0.0" ixz="0.0" iyy="0.00272194058122" iyz="0.0"
        izz="0.0034284375" />
    </inertial>
  </link>

  <!-- Wrist 3 Joint -->
  <joint name="wrist_3_joint" type="revolute">
    <parent link="wrist_2_link" />
    <child link="wrist_3_link" />
    <origin rpy="0 0 0" xyz="0 0 0.1" />
    <axis xyz="0 1 0" />
    <limit effort="28.0" lower="-6.283185307179586" upper="6.283185307179586" velocity="6.28" />
    <dynamics damping="0.0" friction="0.0" />
  </joint>

  <!-- Wrist 3 Link -->
  <link name="wrist_3_link">
    <visual>
      <geometry>
        <mesh filename="../meshes/ur5e_update/visual/wrist3.dae" />
      </geometry>
      <material name="LightGrey">
        <color rgba="0.8 0.8 0.8 1.0" />
      </material>
    </visual>
    <collision>
      <geometry>
        <mesh filename="../meshes/ur5e_update/collision/wrist3.stl" />
      </geometry>
    </collision>
    <inertial>
      <mass value="0.1879" />
      <origin rpy="0 0 0" xyz="0.0 0.0 -0.025" />
      <inertia ixx="0.000134270154625" ixy="0.0" ixz="0.0" iyy="0.000134270154625" iyz="0.0"
        izz="0.00019024875" />
    </inertial>
  </link>

  <!-- ========== Robotiq 2F-85 Gripper Links and Joints ========== -->

  <!-- Gripper Base Link -->
  <link name="robotiq_85_base_link">
    <visual>
      <geometry>
        <mesh filename="../meshes/robotiq/visual/robotiq_base.obj" />
      </geometry>
      <material name="Dark">
        <color rgba="0 0 0 1.0" />
      </material>
    </visual>
    <collision>
      <geometry>
        <mesh filename="../meshes/robotiq/collision/robotiq_base.stl" />
      </geometry>
    </collision>
    <inertial>
      <origin rpy="0 0 0" xyz="0.0 2.274e-05 0.03232288" />
      <mass value="6.6320197e-01" />
      <inertia ixx="5.1617816e-04" ixy="2.936e-8" ixz="0.0" iyy="5.8802208e-04" iyz="-3.2296e-7"
        izz="3.9462776e-04" />
    </inertial>
  </link>

  <!-- Gripper Base Joint -->
  <joint name="robotiq_85_base_joint" type="fixed">
    <parent link="wrist_3_link" />
    <child link="robotiq_85_base_link" />
    <origin rpy="-1.5708 0 0" xyz="0 0.1 0" />
  </joint>

  <!-- Left Knuckle Link -->
  <link name="robotiq_85_left_knuckle_link">
    <visual>
      <geometry>
        <mesh filename="../meshes/robotiq/visual/left_knuckle.obj" />
      </geometry>
      <material name="LightGrey">
        <color rgba="0.8 0.8 0.8 1.0" />
      </material>
    </visual>
    <collision>
      <geometry>
        <mesh filename="../meshes/robotiq/collision/left_knuckle.stl" />
      </geometry>
    </collision>
    <inertial>
      <origin rpy="0 0 0" xyz="0.01213197 0.0002 -0.00058647" />
      <mass value="1.384773208e-02" />
      <inertia ixx="3.5232e-7" ixy="0.0" ixz="1.1744e-7" iyy="2.31944e-6" iyz="0" izz="2.23136e-6" />
    </inertial>
  </link>

  <!-- Left Knuckle Joint -->
  <joint name="robotiq_85_left_knuckle_joint" type="revolute">
    <parent link="robotiq_85_base_link" />
    <child link="robotiq_85_left_knuckle_link" />
    <axis xyz="0 -1 0" />
    <origin rpy="0 0 0" xyz="0.03060114 0.0 0.05490452" />
    <limit effort="50" lower="0.0" upper="0.8" velocity="0.5" />
  </joint>

  <!-- Right Knuckle Link -->
  <link name="robotiq_85_right_knuckle_link">
    <visual>
      <geometry>
        <mesh filename="../meshes/robotiq/visual/right_knuckle.obj" />
      </geometry>
      <material name="LightGrey">
        <color rgba="0.8 0.8 0.8 1.0" />
      </material>
    </visual>
    <collision>
      <geometry>
        <mesh filename="../meshes/robotiq/collision/right_knuckle.stl" />
      </geometry>
    </collision>
    <inertial>
      <origin rpy="0 0 0" xyz="-0.01213197 0.0002 -0.00058647" />
      <mass value="1.384773208e-02" />
      <inertia ixx="3.5232e-7" ixy="0.0" ixz="-1.1744e-7" iyy="2.31944e-6" iyz="0.0"
        izz="2.23136e-6" />
    </inertial>
  </link>

  <!-- Right Knuckle Joint -->
  <joint name="robotiq_85_right_knuckle_joint" type="revolute">
    <parent link="robotiq_85_base_link" />
    <child link="robotiq_85_right_knuckle_link" />
    <axis xyz="0 -1 0" />
    <origin rpy="0 0 0" xyz="-0.03060114 0.0 0.05490452" />
    <limit effort="50" lower="-0.8" upper="0.0" velocity="0.5" />
    <mimic joint="robotiq_85_left_knuckle_joint" multiplier="-1" />
  </joint>

  <!-- Left Finger Link -->
  <link name="robotiq_85_left_finger_link">
    <visual>
      <geometry>
        <mesh filename="../meshes/robotiq/visual/left_finger.obj" />
      </geometry>
      <material name="Dark">
        <color rgba="0 0 0 1.0" />
      </material>
    </visual>
    <collision>
      <geometry>
        <mesh filename="../meshes/robotiq/collision/left_finger.stl" />
      </geometry>
    </collision>
    <inertial>
      <origin rpy="0 0 0" xyz="0.00346899 -0.00079447 0.01867121" />
      <mass value="4.260376752e-02" />
      <inertia ixx="1.385792000000000e-05" ixy="0.0" ixz="-2.17264e-06" iyy="1.183208e-05" iyz="0.0"
        izz="5.19672e-06" />
    </inertial>
  </link>

  <!-- Left Finger Joint -->
  <joint name="robotiq_85_left_finger_joint" type="fixed">
    <parent link="robotiq_85_left_knuckle_link" />
    <child link="robotiq_85_left_finger_link" />
    <origin rpy="0 0 0" xyz="0.03152616 0.0 -0.00376347" />
  </joint>

  <!-- Right Finger Link -->
  <link name="robotiq_85_right_finger_link">
    <visual>
      <geometry>
        <mesh filename="../meshes/robotiq/visual/right_finger.obj" />
      </geometry>
      <material name="Dark">
        <color rgba="0 0 0 1.0" />
      </material>
    </visual>
    <collision>
      <geometry>
        <mesh filename="../meshes/robotiq/collision/right_finger.stl" />
      </geometry>
    </collision>
    <inertial>
      <origin rpy="0 0 0" xyz="-0.00346899 -5.53e-06 0.01867121" />
      <mass value="4.260376752000000e-02" />
      <inertia ixx="1.385792e-05" ixy="0.0" ixz="2.17264e-06" iyy="1.183208e-05" iyz="0.0"
        izz="5.19672e-06" />
    </inertial>
  </link>

  <!-- Right Finger Joint -->
  <joint name="robotiq_85_right_finger_joint" type="fixed">
    <parent link="robotiq_85_right_knuckle_link" />
    <child link="robotiq_85_right_finger_link" />
    <origin rpy="0 0 0" xyz="-0.03152616 0.0 -0.00376347" />
  </joint>

  <!-- Left Inner Knuckle Link -->
  <link name="robotiq_85_left_inner_knuckle_link">
    <visual>
      <geometry>
        <mesh filename="../meshes/robotiq/visual/left_inner_knuckle.obj" />
      </geometry>
      <material name="LightGrey">
        <color rgba="0.8 0.8 0.8 1.0" />
      </material>
    </visual>
    <collision>
      <geometry>
        <mesh filename="../meshes/robotiq/collision/left_inner_knuckle.stl" />
      </geometry>
    </collision>
    <inertial>
      <origin rpy="0 0 0" xyz="0.01897699 0.00015001 0.02247101" />
      <mass value="2.969376448e-02" />
      <inertia ixx="9.57136e-06" ixy="0.0" ixz="-3.93424e-06" iyy="8.69056e-06" iyz="0.0"
        izz="8.19144e-06" />
    </inertial>
  </link>

  <!-- Left Inner Knuckle Joint -->
  <joint name="robotiq_85_left_inner_knuckle_joint" type="continuous">
    <parent link="robotiq_85_base_link" />
    <child link="robotiq_85_left_inner_knuckle_link" />
    <axis xyz="0 -1 0" />
    <origin rpy="0 0 0" xyz="0.0127 0.0 0.06142" />
    <mimic joint="robotiq_85_left_knuckle_joint" />
  </joint>

  <!-- Right Inner Knuckle Link -->
  <link name="robotiq_85_right_inner_knuckle_link">
    <visual>
      <geometry>
        <mesh filename="../meshes/robotiq/visual/right_inner_knuckle.obj" />
      </geometry>
      <material name="LightGrey">
        <color rgba="0.8 0.8 0.8 1.0" />
      </material>
    </visual>
    <collision>
      <geometry>
        <mesh filename="../meshes/robotiq/collision/right_inner_knuckle.stl" />
      </geometry>
    </collision>
    <inertial>
      <origin rpy="0 0 0" xyz="-0.01926824 5.001e-05 0.02222178" />
      <mass value="2.969376448e-02" />
      <inertia ixx="9.42456e-06" ixy="0.0" ixz="3.9636e-06" iyy="8.69056e-06" iyz="0.0"
        izz="8.33824e-06" />
    </inertial>
  </link>

  <!-- Right Inner Knuckle Joint -->
  <joint name="robotiq_85_right_inner_knuckle_joint" type="continuous">
    <parent link="robotiq_85_base_link" />
    <child link="robotiq_85_right_inner_knuckle_link" />
    <axis xyz="0 -1 0" />
    <origin rpy="0 0 0" xyz="-0.0127 0.0 0.06142" />
    <mimic joint="robotiq_85_left_knuckle_joint" multiplier="-1" />
  </joint>

  <!-- Left Finger Tip Link -->
  <link name="robotiq_85_left_finger_tip_link">
    <visual>
      <geometry>
        <mesh filename="../meshes/robotiq/visual/left_finger_tip.obj" />
      </geometry>
      <material name="LightGrey">
        <color rgba="0.8 0.8 0.8 1.0" />
      </material>
    </visual>
    <collision>
      <geometry>
        <mesh filename="../meshes/robotiq/collision/left_finger_tip.stl" />
      </geometry>
      <surface>
        <friction>
          <ode>
            <mu1>1.0</mu1>
            <mu2>1.0</mu2>
          </ode>
        </friction>
        <contact>
          <ode>
            <kp>1e+5</kp>
            <kd>1</kd>
            <soft_cfm>0</soft_cfm>
            <soft_erp>0.2</soft_erp>
            <minDepth>0.002</minDepth>
            <maxVel>0</maxVel>
          </ode>
        </contact>
      </surface>
    </collision>
    <inertial>
      <origin rpy="0 0 0" xyz="-0.01456706 -0.0008 0.01649701" />
      <mass value="4.268588744e-02" />
      <inertia ixx="1.048152e-05" ixy="0.0" ixz="3.5232e-6" iyy="1.197888e-05" iyz="0.0"
        izz="4.22784e-06" />
    </inertial>
  </link>

  <!-- Left Finger Tip Joint -->
  <joint name="robotiq_85_left_finger_tip_joint" type="continuous">
    <parent link="robotiq_85_left_finger_link" />
    <child link="robotiq_85_left_finger_tip_link" />
    <axis xyz="0 -1 0" />
    <origin rpy="0 0 0" xyz="0.00563134 0.0 0.04718515" />
    <mimic joint="robotiq_85_left_knuckle_joint" multiplier="-1" />
  </joint>

  <!-- Right Finger Tip Link -->
  <link name="robotiq_85_right_finger_tip_link">
    <visual>
      <geometry>
        <mesh filename="../meshes/robotiq/visual/right_finger_tip.obj" />
      </geometry>
      <material name="LightGrey">
        <color rgba="0.8 0.8 0.8 1.0" />
      </material>
    </visual>
    <collision>
      <geometry>
        <mesh filename="../meshes/robotiq/collision/right_finger_tip.stl" />
      </geometry>
      <surface>
        <friction>
          <ode>
            <mu1>1.0</mu1>
            <mu2>1.0</mu2>
          </ode>
        </friction>
        <contact>
          <ode>
            <kp>1e+5</kp>
            <kd>1</kd>
            <soft_cfm>0</soft_cfm>
            <soft_erp>0.2</soft_erp>
            <minDepth>0.002</minDepth>
            <maxVel>0</maxVel>
          </ode>
        </contact>
      </surface>
    </collision>
    <inertial>
      <origin rpy="0 0 0" xyz="0.01456706 5e-05 0.01649701" />
      <mass value="4.268588744e-02" />
      <inertia ixx="1.048152e-05" ixy="0.0" ixz="-3.5232e-06" iyy="1.197888e-05" iyz="0.0"
        izz="4.22784e-06" />
    </inertial>
  </link>

  <!-- Right Finger Tip Joint -->
  <joint name="robotiq_85_right_finger_tip_joint" type="continuous">
    <parent link="robotiq_85_right_finger_link" />
    <child link="robotiq_85_right_finger_tip_link" />
    <axis xyz="0 -1 0" />
    <origin rpy="0 0 0" xyz="-0.00563134 0.0 0.04718515" />
    <mimic joint="robotiq_85_left_knuckle_joint" />
  </joint>

  <!-- Gripper Center Link -->
  <link name="gripper_center_link">
    <visual>
      <origin rpy="1.5708 0 0" xyz="0 0 0" />
      <geometry>
        <cylinder length="0.01" radius="0.0001" />
      </geometry>
      <material name="Red">
        <color rgba="1 0 0 0.2" />
      </material>
    </visual>
    <inertial>
      <origin rpy="0 0 0" xyz="0 0 0" />
      <mass value="0.001" />
      <inertia ixx="0.000001" ixy="0" ixz="0" iyy="0.000001" iyz="0" izz="0.000001" />
    </inertial>
  </link>

  <!-- Gripper Center Joint -->
  <joint name="gripper_center_joint" type="fixed">
    <parent link="wrist_3_link" />
    <child link="gripper_center_link" />
    <origin rpy="-1.5708 0.0 0" xyz="0 0.24 0" />
  </joint>

</robot>